2019-02-18 10:57:11,580 ERROR: Exception on /view_profile/Erick [GET] [in c:\anaconda\lib\site-packages\flask\app.py:1761]
Traceback (most recent call last):
  File "c:\anaconda\lib\site-packages\flask\app.py", line 2292, in wsgi_app
    response = self.full_dispatch_request()
  File "c:\anaconda\lib\site-packages\flask\app.py", line 1815, in full_dispatch_request
    rv = self.handle_user_exception(e)
  File "c:\anaconda\lib\site-packages\flask\app.py", line 1718, in handle_user_exception
    reraise(exc_type, exc_value, tb)
  File "c:\anaconda\lib\site-packages\flask\_compat.py", line 35, in reraise
    raise value
  File "c:\anaconda\lib\site-packages\flask\app.py", line 1813, in full_dispatch_request
    rv = self.dispatch_request()
  File "c:\anaconda\lib\site-packages\flask\app.py", line 1799, in dispatch_request
    return self.view_functions[rule.endpoint](**req.view_args)
  File "c:\anaconda\lib\site-packages\flask_login\utils.py", line 261, in decorated_view
    return func(*args, **kwargs)
  File "D:\Projects\Flask\microblog\app\routes.py", line 167, in view_profile
    return render_template("view_profile.html", title="Profiel bekijken", user=user, posts=posts)
  File "c:\anaconda\lib\site-packages\flask\templating.py", line 135, in render_template
    context, ctx.app)
  File "c:\anaconda\lib\site-packages\flask\templating.py", line 117, in _render
    rv = template.render(context)
  File "c:\anaconda\lib\site-packages\jinja2\environment.py", line 1008, in render
    return self.environment.handle_exception(exc_info, True)
  File "c:\anaconda\lib\site-packages\jinja2\environment.py", line 780, in handle_exception
    reraise(exc_type, exc_value, tb)
  File "c:\anaconda\lib\site-packages\jinja2\_compat.py", line 37, in reraise
    raise value.with_traceback(tb)
  File "D:\Projects\Flask\microblog\app\templates\view_profile.html", line 1, in top-level template code
    {% extends "base.html" %}
  File "D:\Projects\Flask\microblog\app\templates\base.html", line 34, in top-level template code
    {% block content %}{% endblock %}
  File "D:\Projects\Flask\microblog\app\templates\view_profile.html", line 35, in block "content"
    {% include 'onepost.html' %}
  File "D:\Projects\Flask\microblog\app\templates\onepost.html", line 7, in top-level template code
    <!-- <a href="{{ url_for('user', username=post.author.name) }}"> -->
  File "c:\anaconda\lib\site-packages\flask\helpers.py", line 356, in url_for
    return appctx.app.handle_url_build_error(error, endpoint, values)
  File "c:\anaconda\lib\site-packages\flask\app.py", line 2061, in handle_url_build_error
    reraise(exc_type, exc_value, tb)
  File "c:\anaconda\lib\site-packages\flask\_compat.py", line 35, in reraise
    raise value
  File "c:\anaconda\lib\site-packages\flask\helpers.py", line 345, in url_for
    force_external=external)
  File "c:\anaconda\lib\site-packages\werkzeug\routing.py", line 1776, in build
    raise BuildError(endpoint, values, method, self)
werkzeug.routing.BuildError: Could not build url for endpoint 'user' with values ['username']. Did you mean 'register' instead?
2019-02-18 10:57:20,658 INFO: Microblog startup [in D:\Projects\Flask\microblog\app\__init__.py:57]
2019-02-18 10:57:38,224 ERROR: Exception on /index [GET] [in c:\anaconda\lib\site-packages\flask\app.py:1761]
Traceback (most recent call last):
  File "c:\anaconda\lib\site-packages\flask\app.py", line 2292, in wsgi_app
    response = self.full_dispatch_request()
  File "c:\anaconda\lib\site-packages\flask\app.py", line 1815, in full_dispatch_request
    rv = self.handle_user_exception(e)
  File "c:\anaconda\lib\site-packages\flask\app.py", line 1718, in handle_user_exception
    reraise(exc_type, exc_value, tb)
  File "c:\anaconda\lib\site-packages\flask\_compat.py", line 35, in reraise
    raise value
  File "c:\anaconda\lib\site-packages\flask\app.py", line 1813, in full_dispatch_request
    rv = self.dispatch_request()
  File "c:\anaconda\lib\site-packages\flask\app.py", line 1799, in dispatch_request
    return self.view_functions[rule.endpoint](**req.view_args)
  File "c:\anaconda\lib\site-packages\flask_login\utils.py", line 261, in decorated_view
    return func(*args, **kwargs)
  File "D:\Projects\Flask\microblog\app\routes.py", line 76, in index
    return render_template('index.html', title='Microblog Home', posts=posts)
  File "c:\anaconda\lib\site-packages\flask\templating.py", line 135, in render_template
    context, ctx.app)
  File "c:\anaconda\lib\site-packages\flask\templating.py", line 117, in _render
    rv = template.render(context)
  File "c:\anaconda\lib\site-packages\jinja2\environment.py", line 1008, in render
    return self.environment.handle_exception(exc_info, True)
  File "c:\anaconda\lib\site-packages\jinja2\environment.py", line 780, in handle_exception
    reraise(exc_type, exc_value, tb)
  File "c:\anaconda\lib\site-packages\jinja2\_compat.py", line 37, in reraise
    raise value.with_traceback(tb)
  File "D:\Projects\Flask\microblog\app\templates\index.html", line 1, in top-level template code
    {% extends "base.html" %}
  File "D:\Projects\Flask\microblog\app\templates\base.html", line 34, in top-level template code
    {% block content %}{% endblock %}
  File "D:\Projects\Flask\microblog\app\templates\index.html", line 22, in block "content"
    {% include 'onepost.html' %}
  File "D:\Projects\Flask\microblog\app\templates\onepost.html", line 7, in top-level template code
    <!-- <a href="{{ url_for('user', username=post.author.name) }}"> -->
  File "c:\anaconda\lib\site-packages\flask\helpers.py", line 356, in url_for
    return appctx.app.handle_url_build_error(error, endpoint, values)
  File "c:\anaconda\lib\site-packages\flask\app.py", line 2061, in handle_url_build_error
    reraise(exc_type, exc_value, tb)
  File "c:\anaconda\lib\site-packages\flask\_compat.py", line 35, in reraise
    raise value
  File "c:\anaconda\lib\site-packages\flask\helpers.py", line 345, in url_for
    force_external=external)
  File "c:\anaconda\lib\site-packages\werkzeug\routing.py", line 1776, in build
    raise BuildError(endpoint, values, method, self)
werkzeug.routing.BuildError: Could not build url for endpoint 'user' with values ['username']. Did you mean 'register' instead?
2019-02-18 10:58:38,896 INFO: Microblog startup [in D:\Projects\Flask\microblog\app\__init__.py:57]
2019-02-18 10:58:44,896 ERROR: Exception on /explore [GET] [in c:\anaconda\lib\site-packages\flask\app.py:1761]
Traceback (most recent call last):
  File "c:\anaconda\lib\site-packages\flask\app.py", line 2292, in wsgi_app
    response = self.full_dispatch_request()
  File "c:\anaconda\lib\site-packages\flask\app.py", line 1815, in full_dispatch_request
    rv = self.handle_user_exception(e)
  File "c:\anaconda\lib\site-packages\flask\app.py", line 1718, in handle_user_exception
    reraise(exc_type, exc_value, tb)
  File "c:\anaconda\lib\site-packages\flask\_compat.py", line 35, in reraise
    raise value
  File "c:\anaconda\lib\site-packages\flask\app.py", line 1813, in full_dispatch_request
    rv = self.dispatch_request()
  File "c:\anaconda\lib\site-packages\flask\app.py", line 1799, in dispatch_request
    return self.view_functions[rule.endpoint](**req.view_args)
  File "c:\anaconda\lib\site-packages\flask_login\utils.py", line 261, in decorated_view
    return func(*args, **kwargs)
  File "D:\Projects\Flask\microblog\app\routes.py", line 38, in explore
    posts = Post.query.order_by(Post.timestamp.desc()).all()
NameError: name 'Post' is not defined
2019-02-18 10:59:28,567 INFO: Microblog startup [in D:\Projects\Flask\microblog\app\__init__.py:57]
2019-02-18 11:08:36,484 INFO: Microblog startup [in D:\Projects\Flask\microblog\app\__init__.py:57]
2019-02-18 11:08:39,900 ERROR: Exception on /index [GET] [in c:\anaconda\lib\site-packages\flask\app.py:1761]
Traceback (most recent call last):
  File "c:\anaconda\lib\site-packages\flask\app.py", line 2292, in wsgi_app
    response = self.full_dispatch_request()
  File "c:\anaconda\lib\site-packages\flask\app.py", line 1815, in full_dispatch_request
    rv = self.handle_user_exception(e)
  File "c:\anaconda\lib\site-packages\flask\app.py", line 1718, in handle_user_exception
    reraise(exc_type, exc_value, tb)
  File "c:\anaconda\lib\site-packages\flask\_compat.py", line 35, in reraise
    raise value
  File "c:\anaconda\lib\site-packages\flask\app.py", line 1813, in full_dispatch_request
    rv = self.dispatch_request()
  File "c:\anaconda\lib\site-packages\flask\app.py", line 1799, in dispatch_request
    return self.view_functions[rule.endpoint](**req.view_args)
  File "c:\anaconda\lib\site-packages\flask_login\utils.py", line 261, in decorated_view
    return func(*args, **kwargs)
  File "D:\Projects\Flask\microblog\app\routes.py", line 78, in index
    posts = current_user.timeline().all().paginate(page, app.config['POSTS_PER_PAGE'], False)
AttributeError: 'list' object has no attribute 'paginate'
2019-02-18 11:10:22,389 INFO: Microblog startup [in D:\Projects\Flask\microblog\app\__init__.py:57]
2019-02-18 11:12:36,945 INFO: Microblog startup [in D:\Projects\Flask\microblog\app\__init__.py:57]
