2019-02-18 11:12:51,228 ERROR: Exception on /index [POST] [in c:\anaconda\lib\site-packages\flask\app.py:1761]
Traceback (most recent call last):
  File "c:\anaconda\lib\site-packages\flask\app.py", line 2292, in wsgi_app
    response = self.full_dispatch_request()
  File "c:\anaconda\lib\site-packages\flask\app.py", line 1815, in full_dispatch_request
    rv = self.handle_user_exception(e)
  File "c:\anaconda\lib\site-packages\flask\app.py", line 1718, in handle_user_exception
    reraise(exc_type, exc_value, tb)
  File "c:\anaconda\lib\site-packages\flask\_compat.py", line 35, in reraise
    raise value
  File "c:\anaconda\lib\site-packages\flask\app.py", line 1813, in full_dispatch_request
    rv = self.dispatch_request()
  File "c:\anaconda\lib\site-packages\flask\app.py", line 1799, in dispatch_request
    return self.view_functions[rule.endpoint](**req.view_args)
  File "c:\anaconda\lib\site-packages\flask_login\utils.py", line 261, in decorated_view
    return func(*args, **kwargs)
  File "D:\Projects\Flask\microblog\app\routes.py", line 73, in index
    db.commit()
AttributeError: 'SQLAlchemy' object has no attribute 'commit'
2019-02-18 11:13:10,735 INFO: Microblog startup [in D:\Projects\Flask\microblog\app\__init__.py:57]
2019-02-18 11:23:04,363 INFO: Microblog startup [in D:\Projects\Flask\microblog\app\__init__.py:57]
2019-02-18 11:23:55,838 INFO: Microblog startup [in D:\Projects\Flask\microblog\app\__init__.py:57]
2019-02-18 11:24:22,003 INFO: Microblog startup [in D:\Projects\Flask\microblog\app\__init__.py:57]
2019-02-18 11:24:54,450 INFO: Microblog startup [in D:\Projects\Flask\microblog\app\__init__.py:57]
2019-02-18 11:25:28,154 INFO: Microblog startup [in D:\Projects\Flask\microblog\app\__init__.py:57]
2019-02-18 11:26:41,450 INFO: Microblog startup [in D:\Projects\Flask\microblog\app\__init__.py:57]
2019-02-18 11:27:28,954 INFO: Microblog startup [in D:\Projects\Flask\microblog\app\__init__.py:57]
2019-02-18 11:30:12,258 INFO: Microblog startup [in D:\Projects\Flask\microblog\app\__init__.py:57]
2019-02-18 11:36:43,563 INFO: Microblog startup [in D:\Projects\Flask\microblog\app\__init__.py:57]
2019-02-18 11:37:20,607 INFO: Microblog startup [in D:\Projects\Flask\microblog\app\__init__.py:57]
2019-02-18 11:39:03,985 ERROR: Exception on /login [POST] [in c:\anaconda\lib\site-packages\flask\app.py:1761]
Traceback (most recent call last):
  File "c:\anaconda\lib\site-packages\flask\app.py", line 2292, in wsgi_app
    response = self.full_dispatch_request()
  File "c:\anaconda\lib\site-packages\flask\app.py", line 1815, in full_dispatch_request
    rv = self.handle_user_exception(e)
  File "c:\anaconda\lib\site-packages\flask\app.py", line 1718, in handle_user_exception
    reraise(exc_type, exc_value, tb)
  File "c:\anaconda\lib\site-packages\flask\_compat.py", line 35, in reraise
    raise value
  File "c:\anaconda\lib\site-packages\flask\app.py", line 1813, in full_dispatch_request
    rv = self.dispatch_request()
  File "c:\anaconda\lib\site-packages\flask\app.py", line 1799, in dispatch_request
    return self.view_functions[rule.endpoint](**req.view_args)
  File "D:\Projects\Flask\microblog\app\routes.py", line 114, in login
    elif user.check_pass(form.pw.data):
  File "D:\Projects\Flask\microblog\app\models.py", line 67, in check_pass
    return check_password_hash(self.passhash, pw)
  File "c:\anaconda\lib\site-packages\werkzeug\security.py", line 245, in check_password_hash
    if pwhash.count('$') < 2:
AttributeError: 'NoneType' object has no attribute 'count'
2019-02-18 11:39:33,342 INFO: Microblog startup [in D:\Projects\Flask\microblog\app\__init__.py:57]
2019-02-18 11:39:36,701 INFO: Microblog startup [in D:\Projects\Flask\microblog\app\__init__.py:57]
2019-02-18 11:40:40,770 INFO: Microblog startup [in D:\Projects\Flask\microblog\app\__init__.py:57]
2019-02-18 11:42:05,798 INFO: Microblog startup [in D:\Projects\Flask\microblog\app\__init__.py:57]
2019-02-18 11:45:10,775 INFO: Microblog startup [in D:\Projects\Flask\microblog\app\__init__.py:57]
2019-02-18 11:47:01,269 INFO: Microblog startup [in D:\Projects\Flask\microblog\app\__init__.py:57]
2019-02-18 11:49:35,321 INFO: Microblog startup [in D:\Projects\Flask\microblog\app\__init__.py:57]
2019-02-18 11:50:51,604 INFO: Microblog startup [in D:\Projects\Flask\microblog\app\__init__.py:57]
2019-02-18 11:52:48,654 INFO: Microblog startup [in D:\Projects\Flask\microblog\app\__init__.py:57]
2019-02-18 12:00:32,903 INFO: Microblog startup [in D:\Projects\Flask\microblog\app\__init__.py:57]
2019-02-18 12:01:13,867 ERROR: Exception on /login [POST] [in c:\anaconda\lib\site-packages\flask\app.py:1761]
Traceback (most recent call last):
  File "c:\anaconda\lib\site-packages\flask\app.py", line 2292, in wsgi_app
    response = self.full_dispatch_request()
  File "c:\anaconda\lib\site-packages\flask\app.py", line 1815, in full_dispatch_request
    rv = self.handle_user_exception(e)
  File "c:\anaconda\lib\site-packages\flask\app.py", line 1718, in handle_user_exception
    reraise(exc_type, exc_value, tb)
  File "c:\anaconda\lib\site-packages\flask\_compat.py", line 35, in reraise
    raise value
  File "c:\anaconda\lib\site-packages\flask\app.py", line 1813, in full_dispatch_request
    rv = self.dispatch_request()
  File "c:\anaconda\lib\site-packages\flask\app.py", line 1799, in dispatch_request
    return self.view_functions[rule.endpoint](**req.view_args)
  File "D:\Projects\Flask\microblog\app\routes.py", line 114, in login
    elif user.check_pass(form.pw.data):
  File "D:\Projects\Flask\microblog\app\models.py", line 69, in check_pass
    logger.warn("Ongeldig wachtwoord voor {}: {}".format(self.name, pw))
NameError: name 'logger' is not defined
2019-02-18 12:01:42,681 INFO: Microblog startup [in D:\Projects\Flask\microblog\app\__init__.py:57]
2019-02-18 12:31:53,888 INFO: Microblog startup [in D:\Projects\Flask\microblog\app\__init__.py:61]
2019-02-18 12:33:07,635 INFO: Microblog startup [in D:\Projects\Flask\microblog\app\__init__.py:61]
2019-02-18 12:33:18,196 INFO: Microblog startup [in D:\Projects\Flask\microblog\app\__init__.py:61]
2019-02-18 12:37:52,650 INFO: Microblog startup [in D:\Projects\Flask\microblog\app\__init__.py:61]
2019-02-18 14:17:37,857 INFO: Microblog startup [in D:\Projects\Flask\microblog\app\__init__.py:61]
2019-02-18 14:17:43,032 INFO: Microblog startup [in D:\Projects\Flask\microblog\app\__init__.py:61]
2019-02-18 14:17:59,448 ERROR: Exception on /forgot_password [GET] [in c:\anaconda\lib\site-packages\flask\app.py:1761]
Traceback (most recent call last):
  File "c:\anaconda\lib\site-packages\flask\app.py", line 2292, in wsgi_app
    response = self.full_dispatch_request()
  File "c:\anaconda\lib\site-packages\flask\app.py", line 1815, in full_dispatch_request
    rv = self.handle_user_exception(e)
  File "c:\anaconda\lib\site-packages\flask\app.py", line 1718, in handle_user_exception
    reraise(exc_type, exc_value, tb)
  File "c:\anaconda\lib\site-packages\flask\_compat.py", line 35, in reraise
    raise value
  File "c:\anaconda\lib\site-packages\flask\app.py", line 1813, in full_dispatch_request
    rv = self.dispatch_request()
  File "c:\anaconda\lib\site-packages\flask\app.py", line 1799, in dispatch_request
    return self.view_functions[rule.endpoint](**req.view_args)
  File "D:\Projects\Flask\microblog\app\routes.py", line 85, in forgot_password
    return render_template('forgot_password.html', title='Herstel wachtwoord', form=form)
  File "c:\anaconda\lib\site-packages\flask\templating.py", line 135, in render_template
    context, ctx.app)
  File "c:\anaconda\lib\site-packages\flask\templating.py", line 117, in _render
    rv = template.render(context)
  File "c:\anaconda\lib\site-packages\jinja2\environment.py", line 1008, in render
    return self.environment.handle_exception(exc_info, True)
  File "c:\anaconda\lib\site-packages\jinja2\environment.py", line 780, in handle_exception
    reraise(exc_type, exc_value, tb)
  File "c:\anaconda\lib\site-packages\jinja2\_compat.py", line 37, in reraise
    raise value.with_traceback(tb)
  File "D:\Projects\Flask\microblog\app\templates\forgot_password.html", line 1, in top-level template code
    {% extends "base.html" %}
  File "D:\Projects\Flask\microblog\app\templates\base.html", line 34, in top-level template code
    {% block content %}{% endblock %}
  File "D:\Projects\Flask\microblog\app\templates\forgot_password.html", line 10, in block "content"
    {% for error in form.email.errors %}
  File "c:\anaconda\lib\site-packages\jinja2\environment.py", line 430, in getattr
    return getattr(obj, attribute)
jinja2.exceptions.UndefinedError: 'app.forms.PasswordForgottenForm object' has no attribute 'email'
2019-02-18 14:18:55,816 INFO: Microblog startup [in D:\Projects\Flask\microblog\app\__init__.py:61]
2019-02-18 14:19:07,542 ERROR: Exception on /forgot_password [POST] [in c:\anaconda\lib\site-packages\flask\app.py:1761]
Traceback (most recent call last):
  File "c:\anaconda\lib\site-packages\flask\app.py", line 2292, in wsgi_app
    response = self.full_dispatch_request()
  File "c:\anaconda\lib\site-packages\flask\app.py", line 1815, in full_dispatch_request
    rv = self.handle_user_exception(e)
  File "c:\anaconda\lib\site-packages\flask\app.py", line 1718, in handle_user_exception
    reraise(exc_type, exc_value, tb)
  File "c:\anaconda\lib\site-packages\flask\_compat.py", line 35, in reraise
    raise value
  File "c:\anaconda\lib\site-packages\flask\app.py", line 1813, in full_dispatch_request
    rv = self.dispatch_request()
  File "c:\anaconda\lib\site-packages\flask\app.py", line 1799, in dispatch_request
    return self.view_functions[rule.endpoint](**req.view_args)
  File "D:\Projects\Flask\microblog\app\routes.py", line 81, in forgot_password
    send_passreset_email(user)
  File "D:\Projects\Flask\microblog\app\email.py", line 27, in send_passreset_email
    token = user.get_resetpass_token()
AttributeError: 'User' object has no attribute 'get_resetpass_token'
