2019-02-20 14:25:26,970 ERROR: Exception on / [GET] [in c:\anaconda\lib\site-packages\flask\app.py:1761]
Traceback (most recent call last):
  File "c:\anaconda\lib\site-packages\flask\app.py", line 2292, in wsgi_app
    response = self.full_dispatch_request()
  File "c:\anaconda\lib\site-packages\flask\app.py", line 1815, in full_dispatch_request
    rv = self.handle_user_exception(e)
  File "c:\anaconda\lib\site-packages\flask\app.py", line 1718, in handle_user_exception
    reraise(exc_type, exc_value, tb)
  File "c:\anaconda\lib\site-packages\flask\_compat.py", line 35, in reraise
    raise value
  File "c:\anaconda\lib\site-packages\flask\app.py", line 1813, in full_dispatch_request
    rv = self.dispatch_request()
  File "c:\anaconda\lib\site-packages\flask\app.py", line 1799, in dispatch_request
    return self.view_functions[rule.endpoint](**req.view_args)
  File "c:\anaconda\lib\site-packages\flask_login\utils.py", line 261, in decorated_view
    return func(*args, **kwargs)
  File "D:\Projects\Flask\microblog\app\routes.py", line 107, in index
    nextpage=next_url, prevpage=prev_url)
  File "c:\anaconda\lib\site-packages\flask\templating.py", line 135, in render_template
    context, ctx.app)
  File "c:\anaconda\lib\site-packages\flask\templating.py", line 117, in _render
    rv = template.render(context)
  File "c:\anaconda\lib\site-packages\jinja2\environment.py", line 1008, in render
    return self.environment.handle_exception(exc_info, True)
  File "c:\anaconda\lib\site-packages\jinja2\environment.py", line 780, in handle_exception
    reraise(exc_type, exc_value, tb)
  File "c:\anaconda\lib\site-packages\jinja2\_compat.py", line 37, in reraise
    raise value.with_traceback(tb)
  File "D:\Projects\Flask\microblog\app\templates\index.html", line 2, in top-level template code
    {% import 'bootstrap/wtf.html' as wtf %}
  File "D:\Projects\Flask\microblog\app\templates\base.html", line 1, in top-level template code
    {% extends "bootstrap/base.html" %}
  File "c:\anaconda\lib\site-packages\flask_bootstrap\templates\bootstrap\base.html", line 1, in top-level template code
    {% block doc -%}
  File "c:\anaconda\lib\site-packages\flask_bootstrap\templates\bootstrap\base.html", line 4, in block "doc"
    {%- block html %}
  File "c:\anaconda\lib\site-packages\flask_bootstrap\templates\bootstrap\base.html", line 20, in block "html"
    {% block body -%}
  File "c:\anaconda\lib\site-packages\flask_bootstrap\templates\bootstrap\base.html", line 26, in block "body"
    {% block scripts %}
  File "D:\Projects\Flask\microblog\app\templates\base.html", line 62, in block "scripts"
    $(source).html('<img src="{{ url_for('images', filename='loading.gif') }}">');
  File "c:\anaconda\lib\site-packages\flask\helpers.py", line 356, in url_for
    return appctx.app.handle_url_build_error(error, endpoint, values)
  File "c:\anaconda\lib\site-packages\flask\app.py", line 2061, in handle_url_build_error
    reraise(exc_type, exc_value, tb)
  File "c:\anaconda\lib\site-packages\flask\_compat.py", line 35, in reraise
    raise value
  File "c:\anaconda\lib\site-packages\flask\helpers.py", line 345, in url_for
    force_external=external)
  File "c:\anaconda\lib\site-packages\werkzeug\routing.py", line 1776, in build
    raise BuildError(endpoint, values, method, self)
werkzeug.routing.BuildError: Could not build url for endpoint 'images' with values ['filename']. Did you mean 'index' instead?
2019-02-20 14:25:27,417 ERROR: Exception on /favicon.ico [GET] [in c:\anaconda\lib\site-packages\flask\app.py:1761]
Traceback (most recent call last):
  File "c:\anaconda\lib\site-packages\flask\app.py", line 1813, in full_dispatch_request
    rv = self.dispatch_request()
  File "c:\anaconda\lib\site-packages\flask\app.py", line 1791, in dispatch_request
    self.raise_routing_exception(req)
  File "c:\anaconda\lib\site-packages\flask\app.py", line 1774, in raise_routing_exception
    raise request.routing_exception
  File "c:\anaconda\lib\site-packages\flask\ctx.py", line 336, in match_request
    self.url_adapter.match(return_rule=True)
  File "c:\anaconda\lib\site-packages\werkzeug\routing.py", line 1581, in match
    raise NotFound()
werkzeug.exceptions.NotFound: 404 Not Found: The requested URL was not found on the server.  If you entered the URL manually please check your spelling and try again.

During handling of the above exception, another exception occurred:

Traceback (most recent call last):
  File "c:\anaconda\lib\site-packages\flask\app.py", line 2292, in wsgi_app
    response = self.full_dispatch_request()
  File "c:\anaconda\lib\site-packages\flask\app.py", line 1815, in full_dispatch_request
    rv = self.handle_user_exception(e)
  File "c:\anaconda\lib\site-packages\flask\app.py", line 1713, in handle_user_exception
    return self.handle_http_exception(e)
  File "c:\anaconda\lib\site-packages\flask\app.py", line 1644, in handle_http_exception
    return handler(e)
  File "D:\Projects\Flask\microblog\app\errors.py", line 6, in not_found_error
    return render_template('404.html'), 404
  File "c:\anaconda\lib\site-packages\flask\templating.py", line 135, in render_template
    context, ctx.app)
  File "c:\anaconda\lib\site-packages\flask\templating.py", line 117, in _render
    rv = template.render(context)
  File "c:\anaconda\lib\site-packages\jinja2\environment.py", line 1008, in render
    return self.environment.handle_exception(exc_info, True)
  File "c:\anaconda\lib\site-packages\jinja2\environment.py", line 780, in handle_exception
    reraise(exc_type, exc_value, tb)
  File "c:\anaconda\lib\site-packages\jinja2\_compat.py", line 37, in reraise
    raise value.with_traceback(tb)
  File "D:\Projects\Flask\microblog\app\templates\404.html", line 1, in top-level template code
    {% extends "base.html" %}
  File "D:\Projects\Flask\microblog\app\templates\base.html", line 1, in top-level template code
    {% extends "bootstrap/base.html" %}
  File "c:\anaconda\lib\site-packages\flask_bootstrap\templates\bootstrap\base.html", line 1, in top-level template code
    {% block doc -%}
  File "c:\anaconda\lib\site-packages\flask_bootstrap\templates\bootstrap\base.html", line 4, in block "doc"
    {%- block html %}
  File "c:\anaconda\lib\site-packages\flask_bootstrap\templates\bootstrap\base.html", line 20, in block "html"
    {% block body -%}
  File "c:\anaconda\lib\site-packages\flask_bootstrap\templates\bootstrap\base.html", line 26, in block "body"
    {% block scripts %}
  File "D:\Projects\Flask\microblog\app\templates\base.html", line 62, in block "scripts"
    $(source).html('<img src="{{ url_for('images', filename='loading.gif') }}">');
  File "c:\anaconda\lib\site-packages\flask\helpers.py", line 356, in url_for
    return appctx.app.handle_url_build_error(error, endpoint, values)
  File "c:\anaconda\lib\site-packages\flask\app.py", line 2061, in handle_url_build_error
    reraise(exc_type, exc_value, tb)
  File "c:\anaconda\lib\site-packages\flask\_compat.py", line 35, in reraise
    raise value
  File "c:\anaconda\lib\site-packages\flask\helpers.py", line 345, in url_for
    force_external=external)
  File "c:\anaconda\lib\site-packages\werkzeug\routing.py", line 1776, in build
    raise BuildError(endpoint, values, method, self)
werkzeug.routing.BuildError: Could not build url for endpoint 'images' with values ['filename']. Did you mean 'index' instead?
2019-02-20 14:25:53,856 INFO: Microblog startup [in D:\Projects\Flask\microblog\app\__init__.py:69]
2019-02-20 14:27:22,887 INFO: Microblog startup [in D:\Projects\Flask\microblog\app\__init__.py:69]
2019-02-20 14:27:25,277 INFO: Microblog startup [in D:\Projects\Flask\microblog\app\__init__.py:69]
2019-02-20 14:28:40,303 INFO: Microblog startup [in D:\Projects\Flask\microblog\app\__init__.py:69]
2019-02-20 14:29:02,703 INFO: Microblog startup [in D:\Projects\Flask\microblog\app\__init__.py:69]
2019-02-20 14:30:47,621 INFO: Microblog startup [in D:\Projects\Flask\microblog\app\__init__.py:69]
2019-02-20 14:31:54,181 INFO: Microblog startup [in D:\Projects\Flask\microblog\app\__init__.py:69]
2019-02-20 14:32:03,843 INFO: Microblog startup [in D:\Projects\Flask\microblog\app\__init__.py:69]
2019-02-20 14:33:04,048 INFO: Microblog startup [in D:\Projects\Flask\microblog\app\__init__.py:69]
2019-02-20 14:33:50,591 INFO: Microblog startup [in D:\Projects\Flask\microblog\app\__init__.py:69]
2019-02-20 14:35:13,538 INFO: Microblog startup [in D:\Projects\Flask\microblog\app\__init__.py:69]
2019-02-20 14:39:17,869 INFO: Microblog startup [in D:\Projects\Flask\microblog\app\__init__.py:69]
2019-02-20 14:40:12,895 INFO: Microblog startup [in D:\Projects\Flask\microblog\app\__init__.py:69]
2019-02-20 15:17:00,945 INFO: Microblog startup [in D:\Projects\Flask\microblog\app\__init__.py:69]
2019-02-20 15:18:05,448 INFO: Microblog startup [in D:\Projects\Flask\microblog\app\__init__.py:69]
