2019-02-18 10:41:49,876 ERROR: Exception on /index [GET] [in c:\anaconda\lib\site-packages\flask\app.py:1761]
Traceback (most recent call last):
  File "c:\anaconda\lib\site-packages\flask\app.py", line 2292, in wsgi_app
    response = self.full_dispatch_request()
  File "c:\anaconda\lib\site-packages\flask\app.py", line 1815, in full_dispatch_request
    rv = self.handle_user_exception(e)
  File "c:\anaconda\lib\site-packages\flask\app.py", line 1718, in handle_user_exception
    reraise(exc_type, exc_value, tb)
  File "c:\anaconda\lib\site-packages\flask\_compat.py", line 35, in reraise
    raise value
  File "c:\anaconda\lib\site-packages\flask\app.py", line 1813, in full_dispatch_request
    rv = self.dispatch_request()
  File "c:\anaconda\lib\site-packages\flask\app.py", line 1799, in dispatch_request
    return self.view_functions[rule.endpoint](**req.view_args)
  File "c:\anaconda\lib\site-packages\flask_login\utils.py", line 261, in decorated_view
    return func(*args, **kwargs)
  File "D:\Projects\Flask\microblog\app\routes.py", line 76, in index
    return render_template('index.html', title='Flask-test', posts=current_user.timeline())
  File "c:\anaconda\lib\site-packages\flask\templating.py", line 135, in render_template
    context, ctx.app)
  File "c:\anaconda\lib\site-packages\flask\templating.py", line 117, in _render
    rv = template.render(context)
  File "c:\anaconda\lib\site-packages\jinja2\environment.py", line 1008, in render
    return self.environment.handle_exception(exc_info, True)
  File "c:\anaconda\lib\site-packages\jinja2\environment.py", line 780, in handle_exception
    reraise(exc_type, exc_value, tb)
  File "c:\anaconda\lib\site-packages\jinja2\_compat.py", line 37, in reraise
    raise value.with_traceback(tb)
  File "D:\Projects\Flask\microblog\app\templates\index.html", line 1, in top-level template code
    {% extends "base.html" %}
  File "D:\Projects\Flask\microblog\app\templates\base.html", line 34, in top-level template code
    {% block content %}{% endblock %}
  File "D:\Projects\Flask\microblog\app\templates\index.html", line 22, in block "content"
    {% include 'onepost.html' %}
  File "D:\Projects\Flask\microblog\app\templates\onepost.html", line 7, in top-level template code
    <a href="{{ url_for('user', username=post.author.name) }}">
  File "c:\anaconda\lib\site-packages\flask\helpers.py", line 356, in url_for
    return appctx.app.handle_url_build_error(error, endpoint, values)
  File "c:\anaconda\lib\site-packages\flask\app.py", line 2061, in handle_url_build_error
    reraise(exc_type, exc_value, tb)
  File "c:\anaconda\lib\site-packages\flask\_compat.py", line 35, in reraise
    raise value
  File "c:\anaconda\lib\site-packages\flask\helpers.py", line 345, in url_for
    force_external=external)
  File "c:\anaconda\lib\site-packages\werkzeug\routing.py", line 1776, in build
    raise BuildError(endpoint, values, method, self)
werkzeug.routing.BuildError: Could not build url for endpoint 'user' with values ['username']. Did you mean 'register' instead?
2019-02-18 10:42:49,186 ERROR: Exception on /index [GET] [in c:\anaconda\lib\site-packages\flask\app.py:1761]
Traceback (most recent call last):
  File "c:\anaconda\lib\site-packages\flask\app.py", line 2292, in wsgi_app
    response = self.full_dispatch_request()
  File "c:\anaconda\lib\site-packages\flask\app.py", line 1815, in full_dispatch_request
    rv = self.handle_user_exception(e)
  File "c:\anaconda\lib\site-packages\flask\app.py", line 1718, in handle_user_exception
    reraise(exc_type, exc_value, tb)
  File "c:\anaconda\lib\site-packages\flask\_compat.py", line 35, in reraise
    raise value
  File "c:\anaconda\lib\site-packages\flask\app.py", line 1813, in full_dispatch_request
    rv = self.dispatch_request()
  File "c:\anaconda\lib\site-packages\flask\app.py", line 1799, in dispatch_request
    return self.view_functions[rule.endpoint](**req.view_args)
  File "c:\anaconda\lib\site-packages\flask_login\utils.py", line 261, in decorated_view
    return func(*args, **kwargs)
  File "D:\Projects\Flask\microblog\app\routes.py", line 76, in index
    return render_template('index.html', title='Flask-test', posts=current_user.timeline())
  File "c:\anaconda\lib\site-packages\flask\templating.py", line 135, in render_template
    context, ctx.app)
  File "c:\anaconda\lib\site-packages\flask\templating.py", line 117, in _render
    rv = template.render(context)
  File "c:\anaconda\lib\site-packages\jinja2\environment.py", line 1008, in render
    return self.environment.handle_exception(exc_info, True)
  File "c:\anaconda\lib\site-packages\jinja2\environment.py", line 780, in handle_exception
    reraise(exc_type, exc_value, tb)
  File "c:\anaconda\lib\site-packages\jinja2\_compat.py", line 37, in reraise
    raise value.with_traceback(tb)
  File "D:\Projects\Flask\microblog\app\templates\index.html", line 1, in top-level template code
    {% extends "base.html" %}
  File "D:\Projects\Flask\microblog\app\templates\base.html", line 34, in top-level template code
    {% block content %}{% endblock %}
  File "D:\Projects\Flask\microblog\app\templates\index.html", line 22, in block "content"
    {% include 'onepost.html' %}
  File "D:\Projects\Flask\microblog\app\templates\onepost.html", line 7, in top-level template code
    <a href="{{ url_for('user', username=post.author.name) }}">
  File "c:\anaconda\lib\site-packages\flask\helpers.py", line 356, in url_for
    return appctx.app.handle_url_build_error(error, endpoint, values)
  File "c:\anaconda\lib\site-packages\flask\app.py", line 2061, in handle_url_build_error
    reraise(exc_type, exc_value, tb)
  File "c:\anaconda\lib\site-packages\flask\_compat.py", line 35, in reraise
    raise value
  File "c:\anaconda\lib\site-packages\flask\helpers.py", line 345, in url_for
    force_external=external)
  File "c:\anaconda\lib\site-packages\werkzeug\routing.py", line 1776, in build
    raise BuildError(endpoint, values, method, self)
werkzeug.routing.BuildError: Could not build url for endpoint 'user' with values ['username']. Did you mean 'register' instead?
2019-02-18 10:44:05,370 INFO: Microblog startup [in D:\Projects\Flask\microblog\app\__init__.py:57]
2019-02-18 10:46:21,194 ERROR: Exception on /index [GET] [in c:\anaconda\lib\site-packages\flask\app.py:1761]
Traceback (most recent call last):
  File "c:\anaconda\lib\site-packages\flask\app.py", line 2292, in wsgi_app
    response = self.full_dispatch_request()
  File "c:\anaconda\lib\site-packages\flask\app.py", line 1815, in full_dispatch_request
    rv = self.handle_user_exception(e)
  File "c:\anaconda\lib\site-packages\flask\app.py", line 1718, in handle_user_exception
    reraise(exc_type, exc_value, tb)
  File "c:\anaconda\lib\site-packages\flask\_compat.py", line 35, in reraise
    raise value
  File "c:\anaconda\lib\site-packages\flask\app.py", line 1813, in full_dispatch_request
    rv = self.dispatch_request()
  File "c:\anaconda\lib\site-packages\flask\app.py", line 1799, in dispatch_request
    return self.view_functions[rule.endpoint](**req.view_args)
  File "c:\anaconda\lib\site-packages\flask_login\utils.py", line 261, in decorated_view
    return func(*args, **kwargs)
  File "D:\Projects\Flask\microblog\app\routes.py", line 76, in index
    return render_template('index.html', title='Flask-test', posts=current_user.timeline())
  File "c:\anaconda\lib\site-packages\flask\templating.py", line 135, in render_template
    context, ctx.app)
  File "c:\anaconda\lib\site-packages\flask\templating.py", line 117, in _render
    rv = template.render(context)
  File "c:\anaconda\lib\site-packages\jinja2\environment.py", line 1008, in render
    return self.environment.handle_exception(exc_info, True)
  File "c:\anaconda\lib\site-packages\jinja2\environment.py", line 780, in handle_exception
    reraise(exc_type, exc_value, tb)
  File "c:\anaconda\lib\site-packages\jinja2\_compat.py", line 37, in reraise
    raise value.with_traceback(tb)
  File "D:\Projects\Flask\microblog\app\templates\index.html", line 1, in top-level template code
    {% extends "base.html" %}
  File "D:\Projects\Flask\microblog\app\templates\base.html", line 34, in top-level template code
    {% block content %}{% endblock %}
  File "D:\Projects\Flask\microblog\app\templates\index.html", line 22, in block "content"
    {% include 'onepost.html' %}
  File "D:\Projects\Flask\microblog\app\templates\onepost.html", line 7, in top-level template code
    <a href="{{ url_for('user', username=post.author.name) }}">
  File "c:\anaconda\lib\site-packages\flask\helpers.py", line 356, in url_for
    return appctx.app.handle_url_build_error(error, endpoint, values)
  File "c:\anaconda\lib\site-packages\flask\app.py", line 2061, in handle_url_build_error
    reraise(exc_type, exc_value, tb)
  File "c:\anaconda\lib\site-packages\flask\_compat.py", line 35, in reraise
    raise value
  File "c:\anaconda\lib\site-packages\flask\helpers.py", line 345, in url_for
    force_external=external)
  File "c:\anaconda\lib\site-packages\werkzeug\routing.py", line 1776, in build
    raise BuildError(endpoint, values, method, self)
werkzeug.routing.BuildError: Could not build url for endpoint 'user' with values ['username']. Did you mean 'register' instead?
2019-02-18 10:49:20,938 INFO: Microblog startup [in D:\Projects\Flask\microblog\app\__init__.py:57]
